[2025-10-25T23:07:54.363+0000] {taskinstance.py:1157} INFO - Dependencies all met for dep_context=non-requeueable deps ti=<TaskInstance: crypto_events_dag.ge_validate_raw manual__2025-10-25T23:07:22+00:00 [queued]>
[2025-10-25T23:07:54.391+0000] {taskinstance.py:1157} INFO - Dependencies all met for dep_context=requeueable deps ti=<TaskInstance: crypto_events_dag.ge_validate_raw manual__2025-10-25T23:07:22+00:00 [queued]>
[2025-10-25T23:07:54.392+0000] {taskinstance.py:1359} INFO - Starting attempt 1 of 1
[2025-10-25T23:07:54.425+0000] {taskinstance.py:1380} INFO - Executing <Task(PythonOperator): ge_validate_raw> on 2025-10-25 23:07:22+00:00
[2025-10-25T23:07:54.443+0000] {standard_task_runner.py:57} INFO - Started process 149 to run task
[2025-10-25T23:07:54.448+0000] {standard_task_runner.py:84} INFO - Running: ['***', 'tasks', 'run', 'crypto_events_dag', 'ge_validate_raw', 'manual__2025-10-25T23:07:22+00:00', '--job-id', '7', '--raw', '--subdir', 'DAGS_FOLDER/crypto_events_dag.py', '--cfg-path', '/tmp/tmp28ojli_0']
[2025-10-25T23:07:54.457+0000] {standard_task_runner.py:85} INFO - Job 7: Subtask ge_validate_raw
[2025-10-25T23:07:54.555+0000] {task_command.py:415} INFO - Running <TaskInstance: crypto_events_dag.ge_validate_raw manual__2025-10-25T23:07:22+00:00 [running]> on host f88ac614cc08
[2025-10-25T23:07:54.731+0000] {taskinstance.py:1660} INFO - Exporting env vars: AIRFLOW_CTX_DAG_OWNER='data-eng' AIRFLOW_CTX_DAG_ID='crypto_events_dag' AIRFLOW_CTX_TASK_ID='ge_validate_raw' AIRFLOW_CTX_EXECUTION_DATE='2025-10-25T23:07:22+00:00' AIRFLOW_CTX_TRY_NUMBER='1' AIRFLOW_CTX_DAG_RUN_ID='manual__2025-10-25T23:07:22+00:00'
[2025-10-25T23:07:54.824+0000] {file_data_context.py:222} INFO - FileDataContext loading fluent config
[2025-10-25T23:07:54.837+0000] {config.py:185} INFO - Loading 'datasources' ->
[]
[2025-10-25T23:07:54.850+0000] {abstract_data_context.py:1236} INFO - Profiler store is not configured; omitting it from active stores
[2025-10-25T23:07:54.855+0000] {abstract_data_context.py:1236} INFO - Profiler store is not configured; omitting it from active stores
[2025-10-25T23:07:55.683+0000] {abstract_data_context.py:1236} INFO - Profiler store is not configured; omitting it from active stores
[2025-10-25T23:07:55.688+0000] {abstract_data_context.py:1236} INFO - Profiler store is not configured; omitting it from active stores
[2025-10-25T23:07:55.774+0000] {abstract_data_context.py:4422} INFO - Usage statistics is disabled; skipping initialization.
[2025-10-25T23:07:55.877+0000] {validator.py:1461} INFO - 	10 expectation(s) included in expectation_suite.
[2025-10-25T23:07:56.187+0000] {taskinstance.py:1935} ERROR - Task failed with exception
Traceback (most recent call last):
  File "/home/airflow/.local/lib/python3.8/site-packages/airflow/operators/python.py", line 192, in execute
    return_value = self.execute_callable()
  File "/home/airflow/.local/lib/python3.8/site-packages/airflow/operators/python.py", line 209, in execute_callable
    return self.python_callable(*self.op_args, **self.op_kwargs)
  File "/opt/airflow/dags/crypto_events_dag.py", line 240, in run_ge_validation
    result = context.run_checkpoint(
  File "/home/airflow/.local/lib/python3.8/site-packages/great_expectations/core/usage_statistics/usage_statistics.py", line 266, in usage_statistics_wrapped_method
    result = func(*args, **kwargs)
  File "/home/airflow/.local/lib/python3.8/site-packages/great_expectations/data_context/data_context/abstract_data_context.py", line 2107, in run_checkpoint
    return self._run_checkpoint(
  File "/home/airflow/.local/lib/python3.8/site-packages/great_expectations/data_context/data_context/abstract_data_context.py", line 2151, in _run_checkpoint
    result: CheckpointResult = checkpoint.run_with_runtime_args(
  File "/home/airflow/.local/lib/python3.8/site-packages/great_expectations/checkpoint/checkpoint.py", line 914, in run_with_runtime_args
    return self.run(**checkpoint_run_arguments)
  File "/home/airflow/.local/lib/python3.8/site-packages/great_expectations/core/usage_statistics/usage_statistics.py", line 266, in usage_statistics_wrapped_method
    result = func(*args, **kwargs)
  File "/home/airflow/.local/lib/python3.8/site-packages/great_expectations/checkpoint/checkpoint.py", line 305, in run
    self._run_validation(
  File "/home/airflow/.local/lib/python3.8/site-packages/great_expectations/checkpoint/checkpoint.py", line 530, in _run_validation
    async_validation_operator_result = async_executor.submit(
  File "/home/airflow/.local/lib/python3.8/site-packages/great_expectations/core/async_executor.py", line 106, in submit
    return AsyncResult(value=fn(*args, **kwargs))
  File "/home/airflow/.local/lib/python3.8/site-packages/great_expectations/validation_operators/validation_operators.py", line 382, in run
    async_executor.submit(
  File "/home/airflow/.local/lib/python3.8/site-packages/great_expectations/core/async_executor.py", line 106, in submit
    return AsyncResult(value=fn(*args, **kwargs))
  File "/home/airflow/.local/lib/python3.8/site-packages/great_expectations/validator/validator.py", line 1675, in validate
    results = self.graph_validate(
  File "/home/airflow/.local/lib/python3.8/site-packages/great_expectations/validator/validator.py", line 1024, in graph_validate
    ) = self._generate_metric_dependency_subgraphs_for_each_expectation_configuration(
  File "/home/airflow/.local/lib/python3.8/site-packages/great_expectations/validator/validator.py", line 1124, in _generate_metric_dependency_subgraphs_for_each_expectation_configuration
    expectation_impl = get_expectation_impl(evaluated_config.expectation_type)
  File "/home/airflow/.local/lib/python3.8/site-packages/great_expectations/expectations/registry.py", line 393, in get_expectation_impl
    raise gx_exceptions.ExpectationNotFoundError(f"{expectation_name} not found")
great_expectations.exceptions.exceptions.ExpectationNotFoundError: expect_column_values_to_be_greater_than not found
[2025-10-25T23:07:56.223+0000] {taskinstance.py:1398} INFO - Marking task as FAILED. dag_id=crypto_events_dag, task_id=ge_validate_raw, execution_date=20251025T230722, start_date=20251025T230754, end_date=20251025T230756
[2025-10-25T23:07:56.254+0000] {standard_task_runner.py:104} ERROR - Failed to execute job 7 for task ge_validate_raw (expect_column_values_to_be_greater_than not found; 149)
[2025-10-25T23:07:56.294+0000] {local_task_job_runner.py:228} INFO - Task exited with return code 1
[2025-10-25T23:07:56.361+0000] {taskinstance.py:2776} INFO - 0 downstream tasks scheduled from follow-on schedule check
