[2025-10-25T23:52:15.912+0000] {taskinstance.py:1157} INFO - Dependencies all met for dep_context=non-requeueable deps ti=<TaskInstance: crypto_events_dag.vacuum_analyze_prod scheduled__2025-10-24T00:00:00+00:00 [queued]>
[2025-10-25T23:52:15.923+0000] {taskinstance.py:1157} INFO - Dependencies all met for dep_context=requeueable deps ti=<TaskInstance: crypto_events_dag.vacuum_analyze_prod scheduled__2025-10-24T00:00:00+00:00 [queued]>
[2025-10-25T23:52:15.923+0000] {taskinstance.py:1359} INFO - Starting attempt 1 of 1
[2025-10-25T23:52:15.942+0000] {taskinstance.py:1380} INFO - Executing <Task(PythonOperator): vacuum_analyze_prod> on 2025-10-24 00:00:00+00:00
[2025-10-25T23:52:15.957+0000] {standard_task_runner.py:57} INFO - Started process 232 to run task
[2025-10-25T23:52:15.960+0000] {standard_task_runner.py:84} INFO - Running: ['***', 'tasks', 'run', 'crypto_events_dag', 'vacuum_analyze_prod', 'scheduled__2025-10-24T00:00:00+00:00', '--job-id', '7', '--raw', '--subdir', 'DAGS_FOLDER/crypto_events_dag.py', '--cfg-path', '/tmp/tmp437tuau5']
[2025-10-25T23:52:15.961+0000] {standard_task_runner.py:85} INFO - Job 7: Subtask vacuum_analyze_prod
[2025-10-25T23:52:16.029+0000] {task_command.py:415} INFO - Running <TaskInstance: crypto_events_dag.vacuum_analyze_prod scheduled__2025-10-24T00:00:00+00:00 [running]> on host b3f230ac7af6
[2025-10-25T23:52:16.119+0000] {taskinstance.py:1660} INFO - Exporting env vars: AIRFLOW_CTX_DAG_OWNER='data-eng' AIRFLOW_CTX_DAG_ID='crypto_events_dag' AIRFLOW_CTX_TASK_ID='vacuum_analyze_prod' AIRFLOW_CTX_EXECUTION_DATE='2025-10-24T00:00:00+00:00' AIRFLOW_CTX_TRY_NUMBER='1' AIRFLOW_CTX_DAG_RUN_ID='scheduled__2025-10-24T00:00:00+00:00'
[2025-10-25T23:52:16.133+0000] {base.py:73} INFO - Using connection ID 'crypto_postgres' for task execution.
[2025-10-25T23:52:16.142+0000] {sql.py:418} INFO - Running statement: VACUUM (ANALYZE) prod.bt_crypto_events, parameters: None
[2025-10-25T23:52:16.143+0000] {taskinstance.py:1935} ERROR - Task failed with exception
Traceback (most recent call last):
  File "/home/airflow/.local/lib/python3.8/site-packages/airflow/operators/python.py", line 192, in execute
    return_value = self.execute_callable()
  File "/home/airflow/.local/lib/python3.8/site-packages/airflow/operators/python.py", line 209, in execute_callable
    return self.python_callable(*self.op_args, **self.op_kwargs)
  File "/opt/airflow/dags/crypto_events_dag.py", line 328, in vacuum_analyze_prod
    PostgresHook(postgres_conn_id=POSTGRES_CONN_ID).run(
  File "/home/airflow/.local/lib/python3.8/site-packages/airflow/providers/common/sql/hooks/sql.py", line 392, in run
    self._run_command(cur, sql_statement, parameters)
  File "/home/airflow/.local/lib/python3.8/site-packages/airflow/providers/common/sql/hooks/sql.py", line 423, in _run_command
    cur.execute(sql_statement)
psycopg2.errors.ActiveSqlTransaction: VACUUM cannot run inside a transaction block

[2025-10-25T23:52:16.158+0000] {taskinstance.py:1398} INFO - Marking task as FAILED. dag_id=crypto_events_dag, task_id=vacuum_analyze_prod, execution_date=20251024T000000, start_date=20251025T235215, end_date=20251025T235216
[2025-10-25T23:52:16.174+0000] {standard_task_runner.py:104} ERROR - Failed to execute job 7 for task vacuum_analyze_prod (VACUUM cannot run inside a transaction block
; 232)
[2025-10-25T23:52:16.185+0000] {local_task_job_runner.py:228} INFO - Task exited with return code 1
[2025-10-25T23:52:16.209+0000] {taskinstance.py:2776} INFO - 0 downstream tasks scheduled from follow-on schedule check
