[2025-10-25T23:17:04.391+0000] {taskinstance.py:1157} INFO - Dependencies all met for dep_context=non-requeueable deps ti=<TaskInstance: crypto_events_dag.ge_validate_raw manual__2025-10-25T23:16:40+00:00 [queued]>
[2025-10-25T23:17:04.416+0000] {taskinstance.py:1157} INFO - Dependencies all met for dep_context=requeueable deps ti=<TaskInstance: crypto_events_dag.ge_validate_raw manual__2025-10-25T23:16:40+00:00 [queued]>
[2025-10-25T23:17:04.417+0000] {taskinstance.py:1359} INFO - Starting attempt 1 of 1
[2025-10-25T23:17:04.456+0000] {taskinstance.py:1380} INFO - Executing <Task(PythonOperator): ge_validate_raw> on 2025-10-25 23:16:40+00:00
[2025-10-25T23:17:04.480+0000] {standard_task_runner.py:57} INFO - Started process 238 to run task
[2025-10-25T23:17:04.487+0000] {standard_task_runner.py:84} INFO - Running: ['***', 'tasks', 'run', 'crypto_events_dag', 'ge_validate_raw', 'manual__2025-10-25T23:16:40+00:00', '--job-id', '14', '--raw', '--subdir', 'DAGS_FOLDER/crypto_events_dag.py', '--cfg-path', '/tmp/tmpqo2qc_xl']
[2025-10-25T23:17:04.489+0000] {standard_task_runner.py:85} INFO - Job 14: Subtask ge_validate_raw
[2025-10-25T23:17:04.593+0000] {task_command.py:415} INFO - Running <TaskInstance: crypto_events_dag.ge_validate_raw manual__2025-10-25T23:16:40+00:00 [running]> on host f88ac614cc08
[2025-10-25T23:17:04.773+0000] {taskinstance.py:1660} INFO - Exporting env vars: AIRFLOW_CTX_DAG_OWNER='data-eng' AIRFLOW_CTX_DAG_ID='crypto_events_dag' AIRFLOW_CTX_TASK_ID='ge_validate_raw' AIRFLOW_CTX_EXECUTION_DATE='2025-10-25T23:16:40+00:00' AIRFLOW_CTX_TRY_NUMBER='1' AIRFLOW_CTX_DAG_RUN_ID='manual__2025-10-25T23:16:40+00:00'
[2025-10-25T23:17:04.786+0000] {warnings.py:109} WARNING - /home/***/.local/lib/python3.8/site-packages/great_expectations/data_context/data_context/serializable_data_context.py:225: UserWarning: Warning. An existing `great_expectations.yml` was found here: /opt/***/gx.
    - No action was taken.
  warnings.warn(message)

[2025-10-25T23:17:04.788+0000] {warnings.py:109} WARNING - /home/***/.local/lib/python3.8/site-packages/great_expectations/data_context/data_context/serializable_data_context.py:235: UserWarning: Warning. An existing `config_variables.yml` was found here: /opt/***/gx/uncommitted.
    - No action was taken.
  warnings.warn(message)

[2025-10-25T23:17:04.858+0000] {file_data_context.py:222} INFO - FileDataContext loading fluent config
[2025-10-25T23:17:04.863+0000] {config.py:185} INFO - Loading 'datasources' ->
[]
[2025-10-25T23:17:04.875+0000] {abstract_data_context.py:1236} INFO - Profiler store is not configured; omitting it from active stores
[2025-10-25T23:17:04.880+0000] {abstract_data_context.py:1236} INFO - Profiler store is not configured; omitting it from active stores
[2025-10-25T23:17:05.680+0000] {abstract_data_context.py:1236} INFO - Profiler store is not configured; omitting it from active stores
[2025-10-25T23:17:05.683+0000] {abstract_data_context.py:1236} INFO - Profiler store is not configured; omitting it from active stores
[2025-10-25T23:17:05.766+0000] {abstract_data_context.py:4422} INFO - Usage statistics is disabled; skipping initialization.
[2025-10-25T23:17:05.868+0000] {validator.py:1461} INFO - 	10 expectation(s) included in expectation_suite.
[2025-10-25T23:17:06.516+0000] {logging_mixin.py:151} WARNING - Calculating Metrics:   0%|          | 0/61 [00:00<?, ?it/s]
[2025-10-25T23:17:06.517+0000] {logging_mixin.py:151} WARNING - Calculating Metrics:   0%|          | 0/61 [00:00<?, ?it/s]
[2025-10-25T23:17:06.529+0000] {logging_mixin.py:151} WARNING - Calculating Metrics:   3%|3         | 2/61 [00:00<00:00, 159.71it/s]
[2025-10-25T23:17:06.623+0000] {logging_mixin.py:151} WARNING - Calculating Metrics:   3%|3         | 2/61 [00:00<00:03, 18.87it/s] 
[2025-10-25T23:17:06.623+0000] {logging_mixin.py:151} WARNING - Calculating Metrics:   3%|3         | 2/61 [00:00<00:03, 18.87it/s]
[2025-10-25T23:17:06.631+0000] {logging_mixin.py:151} WARNING - Calculating Metrics:   7%|6         | 4/61 [00:00<00:03, 18.87it/s]
[2025-10-25T23:17:06.738+0000] {logging_mixin.py:151} WARNING - Calculating Metrics:   7%|6         | 4/61 [00:00<00:03, 17.94it/s]
[2025-10-25T23:17:06.739+0000] {logging_mixin.py:151} WARNING - Calculating Metrics:   7%|6         | 4/61 [00:00<00:03, 17.94it/s]
[2025-10-25T23:17:06.759+0000] {logging_mixin.py:151} WARNING - Calculating Metrics:  25%|##4       | 15/61 [00:00<00:02, 17.94it/s]
[2025-10-25T23:17:06.834+0000] {logging_mixin.py:151} WARNING - Calculating Metrics:  25%|##4       | 15/61 [00:00<00:02, 17.94it/s]
[2025-10-25T23:17:06.918+0000] {logging_mixin.py:151} WARNING - Calculating Metrics:  82%|########1 | 50/61 [00:00<00:00, 154.74it/s]
[2025-10-25T23:17:06.919+0000] {logging_mixin.py:151} WARNING - Calculating Metrics:  82%|########1 | 50/61 [00:00<00:00, 154.74it/s]
[2025-10-25T23:17:06.976+0000] {logging_mixin.py:151} WARNING - Calculating Metrics:  82%|########1 | 50/61 [00:00<00:00, 154.74it/s]
[2025-10-25T23:17:07.005+0000] {logging_mixin.py:151} WARNING - Calculating Metrics: 100%|##########| 61/61 [00:00<00:00, 154.74it/s]
[2025-10-25T23:17:07.042+0000] {logging_mixin.py:151} WARNING - Calculating Metrics: 100%|##########| 61/61 [00:00<00:00, 154.74it/s]
[2025-10-25T23:17:07.042+0000] {logging_mixin.py:151} WARNING - Calculating Metrics: 100%|##########| 61/61 [00:00<00:00, 154.74it/s]
[2025-10-25T23:17:07.043+0000] {logging_mixin.py:151} WARNING - Calculating Metrics: 100%|##########| 61/61 [00:00<00:00, 115.85it/s]
[2025-10-25T23:17:09.681+0000] {validator.py:1461} INFO - 	7 expectation(s) included in expectation_suite.
[2025-10-25T23:17:09.720+0000] {taskinstance.py:1935} ERROR - Task failed with exception
Traceback (most recent call last):
  File "/home/airflow/.local/lib/python3.8/site-packages/airflow/operators/python.py", line 192, in execute
    return_value = self.execute_callable()
  File "/home/airflow/.local/lib/python3.8/site-packages/airflow/operators/python.py", line 209, in execute_callable
    return self.python_callable(*self.op_args, **self.op_kwargs)
  File "/opt/airflow/dags/crypto_events_dag.py", line 243, in run_ge_validation
    result = context.run_checkpoint(
  File "/home/airflow/.local/lib/python3.8/site-packages/great_expectations/core/usage_statistics/usage_statistics.py", line 266, in usage_statistics_wrapped_method
    result = func(*args, **kwargs)
  File "/home/airflow/.local/lib/python3.8/site-packages/great_expectations/data_context/data_context/abstract_data_context.py", line 2107, in run_checkpoint
    return self._run_checkpoint(
  File "/home/airflow/.local/lib/python3.8/site-packages/great_expectations/data_context/data_context/abstract_data_context.py", line 2151, in _run_checkpoint
    result: CheckpointResult = checkpoint.run_with_runtime_args(
  File "/home/airflow/.local/lib/python3.8/site-packages/great_expectations/checkpoint/checkpoint.py", line 914, in run_with_runtime_args
    return self.run(**checkpoint_run_arguments)
  File "/home/airflow/.local/lib/python3.8/site-packages/great_expectations/core/usage_statistics/usage_statistics.py", line 266, in usage_statistics_wrapped_method
    result = func(*args, **kwargs)
  File "/home/airflow/.local/lib/python3.8/site-packages/great_expectations/checkpoint/checkpoint.py", line 305, in run
    self._run_validation(
  File "/home/airflow/.local/lib/python3.8/site-packages/great_expectations/checkpoint/checkpoint.py", line 530, in _run_validation
    async_validation_operator_result = async_executor.submit(
  File "/home/airflow/.local/lib/python3.8/site-packages/great_expectations/core/async_executor.py", line 106, in submit
    return AsyncResult(value=fn(*args, **kwargs))
  File "/home/airflow/.local/lib/python3.8/site-packages/great_expectations/validation_operators/validation_operators.py", line 382, in run
    async_executor.submit(
  File "/home/airflow/.local/lib/python3.8/site-packages/great_expectations/core/async_executor.py", line 106, in submit
    return AsyncResult(value=fn(*args, **kwargs))
  File "/home/airflow/.local/lib/python3.8/site-packages/great_expectations/validator/validator.py", line 1675, in validate
    results = self.graph_validate(
  File "/home/airflow/.local/lib/python3.8/site-packages/great_expectations/validator/validator.py", line 1024, in graph_validate
    ) = self._generate_metric_dependency_subgraphs_for_each_expectation_configuration(
  File "/home/airflow/.local/lib/python3.8/site-packages/great_expectations/validator/validator.py", line 1124, in _generate_metric_dependency_subgraphs_for_each_expectation_configuration
    expectation_impl = get_expectation_impl(evaluated_config.expectation_type)
  File "/home/airflow/.local/lib/python3.8/site-packages/great_expectations/expectations/registry.py", line 393, in get_expectation_impl
    raise gx_exceptions.ExpectationNotFoundError(f"{expectation_name} not found")
great_expectations.exceptions.exceptions.ExpectationNotFoundError: expect_query_result_to_be_between not found
[2025-10-25T23:17:09.757+0000] {taskinstance.py:1398} INFO - Marking task as FAILED. dag_id=crypto_events_dag, task_id=ge_validate_raw, execution_date=20251025T231640, start_date=20251025T231704, end_date=20251025T231709
[2025-10-25T23:17:09.791+0000] {standard_task_runner.py:104} ERROR - Failed to execute job 14 for task ge_validate_raw (expect_query_result_to_be_between not found; 238)
[2025-10-25T23:17:09.869+0000] {local_task_job_runner.py:228} INFO - Task exited with return code 1
[2025-10-25T23:17:09.925+0000] {taskinstance.py:2776} INFO - 0 downstream tasks scheduled from follow-on schedule check
